const x = 10

try {

    x = 5

} catch (err) {

    console.log(`Erro: ${err}`)
}